<?xml version="1.0" encoding="UTF-8"?><testsuite name="nosetests" tests="6" errors="0" failures="1" skip="0"><testcase classname="ExperimentTest.MyTestCase" name="test_t1" time="0.000"></testcase><testcase classname="ExperimentTest.MyTestCase" name="test_t2" time="0.000"></testcase><testcase classname="ExperimentTest.MyTestCase" name="test_t3" time="0.000"></testcase><testcase classname="ExperimentTest.MyTestCase" name="test_t4" time="0.000"></testcase><testcase classname="ExperimentTest.MyTestCase" name="test_t5" time="0.000"></testcase><testcase classname="ExperimentTest.MyTestCase" name="test_t6" time="0.000"><failure type="exceptions.AssertionError" message="0 != -1"><![CDATA[Traceback (most recent call last):
  File "/System/Library/Frameworks/Python.framework/Versions/2.7/lib/python2.7/unittest/case.py", line 331, in run
    testMethod()
  File "/Users/XiaoqingXu/Projects/APT_Fall_15/lab3/ExperimentTest.py", line 28, in test_t6
    self.assertEqual(r1, -1)
  File "/System/Library/Frameworks/Python.framework/Versions/2.7/lib/python2.7/unittest/case.py", line 515, in assertEqual
    assertion_func(first, second, msg=msg)
  File "/System/Library/Frameworks/Python.framework/Versions/2.7/lib/python2.7/unittest/case.py", line 508, in _baseAssertEqual
    raise self.failureException(msg)
AssertionError: 0 != -1
]]></failure></testcase></testsuite>